2020-04-20 02:12:04,078 ERROR   MainThread:17828 [retry.py:__call__():108] Retry attempt failed:
Traceback (most recent call last):
  File "/home/tmarcu/.conda/envs/brain2brain_env/lib/python3.7/site-packages/urllib3/connection.py", line 157, in _new_conn
    (self._dns_host, self.port), self.timeout, **extra_kw
  File "/home/tmarcu/.conda/envs/brain2brain_env/lib/python3.7/site-packages/urllib3/util/connection.py", line 61, in create_connection
    for res in socket.getaddrinfo(host, port, family, socket.SOCK_STREAM):
  File "/home/tmarcu/.conda/envs/brain2brain_env/lib/python3.7/socket.py", line 752, in getaddrinfo
    for res in _socket.getaddrinfo(host, port, family, type, proto, flags):
socket.gaierror: [Errno -2] Name or service not known

During handling of the above exception, another exception occurred:

Traceback (most recent call last):
  File "/home/tmarcu/.conda/envs/brain2brain_env/lib/python3.7/site-packages/urllib3/connectionpool.py", line 672, in urlopen
    chunked=chunked,
  File "/home/tmarcu/.conda/envs/brain2brain_env/lib/python3.7/site-packages/urllib3/connectionpool.py", line 376, in _make_request
    self._validate_conn(conn)
  File "/home/tmarcu/.conda/envs/brain2brain_env/lib/python3.7/site-packages/urllib3/connectionpool.py", line 994, in _validate_conn
    conn.connect()
  File "/home/tmarcu/.conda/envs/brain2brain_env/lib/python3.7/site-packages/urllib3/connection.py", line 300, in connect
    conn = self._new_conn()
  File "/home/tmarcu/.conda/envs/brain2brain_env/lib/python3.7/site-packages/urllib3/connection.py", line 169, in _new_conn
    self, "Failed to establish a new connection: %s" % e
urllib3.exceptions.NewConnectionError: <urllib3.connection.VerifiedHTTPSConnection object at 0x2b36a7290810>: Failed to establish a new connection: [Errno -2] Name or service not known

During handling of the above exception, another exception occurred:

Traceback (most recent call last):
  File "/home/tmarcu/.conda/envs/brain2brain_env/lib/python3.7/site-packages/requests/adapters.py", line 449, in send
    timeout=timeout
  File "/home/tmarcu/.conda/envs/brain2brain_env/lib/python3.7/site-packages/urllib3/connectionpool.py", line 720, in urlopen
    method, url, error=e, _pool=self, _stacktrace=sys.exc_info()[2]
  File "/home/tmarcu/.conda/envs/brain2brain_env/lib/python3.7/site-packages/urllib3/util/retry.py", line 436, in increment
    raise MaxRetryError(_pool, url, error or ResponseError(cause))
urllib3.exceptions.MaxRetryError: HTTPSConnectionPool(host='api.wandb.ai', port=443): Max retries exceeded with url: /graphql (Caused by NewConnectionError('<urllib3.connection.VerifiedHTTPSConnection object at 0x2b36a7290810>: Failed to establish a new connection: [Errno -2] Name or service not known'))

During handling of the above exception, another exception occurred:

Traceback (most recent call last):
  File "/home/tmarcu/.conda/envs/brain2brain_env/lib/python3.7/site-packages/wandb/retry.py", line 95, in __call__
    result = self._call_fn(*args, **kwargs)
  File "/home/tmarcu/.conda/envs/brain2brain_env/lib/python3.7/site-packages/wandb/apis/internal.py", line 110, in execute
    return self.client.execute(*args, **kwargs)
  File "/home/tmarcu/.conda/envs/brain2brain_env/lib/python3.7/site-packages/gql/client.py", line 52, in execute
    result = self._get_result(document, *args, **kwargs)
  File "/home/tmarcu/.conda/envs/brain2brain_env/lib/python3.7/site-packages/gql/client.py", line 60, in _get_result
    return self.transport.execute(document, *args, **kwargs)
  File "/home/tmarcu/.conda/envs/brain2brain_env/lib/python3.7/site-packages/gql/transport/requests.py", line 38, in execute
    request = requests.post(self.url, **post_args)
  File "/home/tmarcu/.conda/envs/brain2brain_env/lib/python3.7/site-packages/requests/api.py", line 119, in post
    return request('post', url, data=data, json=json, **kwargs)
  File "/home/tmarcu/.conda/envs/brain2brain_env/lib/python3.7/site-packages/requests/api.py", line 61, in request
    return session.request(method=method, url=url, **kwargs)
  File "/home/tmarcu/.conda/envs/brain2brain_env/lib/python3.7/site-packages/requests/sessions.py", line 530, in request
    resp = self.send(prep, **send_kwargs)
  File "/home/tmarcu/.conda/envs/brain2brain_env/lib/python3.7/site-packages/requests/sessions.py", line 643, in send
    r = adapter.send(request, **kwargs)
  File "/home/tmarcu/.conda/envs/brain2brain_env/lib/python3.7/site-packages/requests/adapters.py", line 516, in send
    raise ConnectionError(e, request=request)
requests.exceptions.ConnectionError: HTTPSConnectionPool(host='api.wandb.ai', port=443): Max retries exceeded with url: /graphql (Caused by NewConnectionError('<urllib3.connection.VerifiedHTTPSConnection object at 0x2b36a7290810>: Failed to establish a new connection: [Errno -2] Name or service not known'))
